<?xml version="1.0"?>

<robot name="threedofexample">

  <!-- ******************************************************** -->
  <!-- ******************* Kinematic Chain ******************** -->
  <!-- ******************************************************** -->
  <!-- Note the 'origin' tag in the joints defines the shift and
       reorientation, i.e. the transform.  For moving joints, this
       happens before the continuous joint rotates around 'axis'. -->

  <!-- World can't take a visual element (at least in Gazebo). -->
  <link name="world"/>

  <joint name="placement" type="fixed">
    <parent link="world"/>
    <child  link="baseplate"/>
    <origin xyz="0.36325 -0.03234 0" rpy="0 0 0"/>			<!-- WHERE IS THE BASE -->
  </joint>

  <!-- BASE PLATE: Shift across the base plate to the base motor. --> 
  <link name="baseplate">
    <visual>
      <origin xyz="0.0 0.025 0.00615" rpy="0 0 0"/>
      <geometry>
	<box size="0.2 0.1 0.0124"/>
      </geometry>
      <material name="wood"/>
    </visual>
  </link>

  <joint name="baseplate" type="fixed">
    <parent link="baseplate"/>
    <child  link="basemotor"/>
    <origin xyz="0 0 0.01240" rpy="0 0 -1.5708"/>
  </joint>

  <!-- BASE MOTOR: Thickness: X5 = 31.1mm, X8 = 45.1mm -->
  <link name="basemotor">
    <visual>
      <geometry>
        <mesh filename="package://threedof/meshes/X8.stl"
	      scale="0.001 0.001 0.001"/>
      </geometry>
      <material name="hebi"/>
    </visual>
  </link>

  <joint name="base" type="continuous">
    <parent link="basemotor"/>
    <child  link="lbracket"/>
    <origin xyz="0 0 0.0449" rpy="0 0 0"/>
    <axis   xyz="0 0 1"/>
  </joint>

  <!-- L BRACKET: Shift and rotate across the L bracket. -->
  <link name="lbracket">
    <!-- Add a visual element -->
  </link>

  <joint name="lbracket" type="fixed">
    <parent link="lbracket"/>
    <child  link="shouldermotor"/>
    <origin xyz="-0.03234 0 0.11" rpy="0 -1.5708 3.1415"/>	  <!-- L BRACKET DIMENIONS -->
  </joint>
  

  <!-- SHOULDER MOTOR: Thickness: X5 = 31.1mm, X8 = 45.1mm -->
  <link name="shouldermotor">
    <visual>
      <geometry>
        <mesh filename="package://threedof/meshes/X5.stl"
	      scale="0.001 0.001 0.001"/>
      </geometry>
      <material name="hebi"/>
    </visual>
  </link>

  <joint name="shoulder" type="continuous">
    <parent link="shouldermotor"/>
    <child  link="upperarm"/>
    <origin xyz="0 0 0.0308" rpy="0 0 0"/>
    <axis   xyz="0 0 1"/>
  </joint>

  <!-- UPPER ARM: Shift across the upper arm (1/4in thickness) -->
  <link name="upperarm">
    <visual>
      <origin xyz="0.1925 0 0.00284" rpy="0 0 0"/>
      <geometry>
	<box size="0.456 0.075 0.00568"/>
      </geometry>
      <material name="wood"/>
    </visual>
  <!--Add a visual element> -->
  </link> 


 <!-- UPPER ARM: Shift across the upper arm (1/4in thickness) -->
  <!-- <link name="upperarm">
    <visual>
      <geometry>
        <mesh filename="package://threedof/meshes/upperarm.stl" 
        scale="0.001 0.001 0.001" />
      <collision>
        <origin xyz="0.0 0.0 0.0" rpy="1.5708 3.1415 0"/>
      </collision>
      </geometry>
      <material name="wood"/>
    </visual>
  </link> -->

  <joint name="upperarm" type="fixed">
    <parent link="upperarm"/>
    <child  link="elbowmotor"/>
    <origin xyz="0.385 0 0" rpy="3.1415 0 3.1415"/>		  <!-- UPPER ARM DIMENIONS -->
  </joint>

  <!-- Elbow motor.  Thickness: X5 = 31.1mm, X8 = 45.1mm -->
  <link name="elbowmotor">
    <visual>
      <geometry>
        <mesh filename="package://threedof/meshes/X5.stl"
	      scale="0.001 0.001 0.001"/>
      </geometry>
      <material name="hebi"/>
    </visual>
  </link>

  <joint name="elbow" type="continuous">
    <parent link="elbowmotor"/>
    <child  link="lowerarm"/>
    <origin xyz="0.0 0.0 0.0308" rpy="0 0 3.1415"/>
    <axis   xyz="0 0 1"/>
  </joint>

  <!-- Shift across the upper arm (1/4in thickness) -->
  <!-- <link name="lowerarm">
    <visual>
      <geometry>
        <mesh filename="package://threedof/meshes/basiclink.stl"/>
      </geometry>
      <material name="wood"/>
    </visual>
  </link> -->

  <link name="lowerarm">
    <visual>
      <origin xyz="0.185 0 0.00284" rpy="0 0 0"/>
      <geometry>
	<box size="0.37 0.075 0.00568"/>
      </geometry>
      <material name="wood"/>
    </visual>
  <!--Add a visual element> -->
  </link> 


  <joint name="lowerarm" type="fixed">
    <parent link="lowerarm"/>
    <child  link="tip"/>
    <origin xyz="0.37 0 0.00285" rpy="0 0 0"/>		  <!-- UPPER ARM DIMENIONS -->
  </joint>

  <!-- TIP FRAME -->
  <link name="tip"/>

  
  <!-- *************************************************** -->
  <!-- *************** Visual Link Elements ************** -->
  <!-- *************************************************** -->
  <!-- Note collada .dae files have better color/texture   -->
  <!-- suppport that STL files.                            -->

  <!-- Colors -->
  <material name="wood">  <color rgba="0.82 0.62 0.04 1"/>  </material>
  <material name="hebi">  <color rgba="0.82 0.06 0.06 1"/>  </material>

</robot>
